<?xml version='1.0'?>
<sdf version='1.7'>

  <odom_publish_frequency>1</odom_publish_frequency>
  <topic>cmd_vel</topic>

  <model name="marble">
    <link name="base_link">
      <pose frame="">0 0 0 0 -0 0</pose>
      <inertial>
        <mass>21.8194</mass>
        <inertia>
          <ixx>0.33184 </ixx>
          <ixy>0.0</ixy>
          <ixz>0.0</ixz>
          <iyy>1.81366</iyy>
          <iyz>0.0</iyz>
          <izz>2.06368</izz>
        </inertia>
      </inertial>
      <collision name="base_link_collision">
        <pose frame="">0 0 0.12 0 0 0</pose>
        <geometry>
          <box>
            <size>0.9874 0.5709 0.05</size>
          </box>
        </geometry>
      </collision>
      <collision name="base_link_collision_bottom">
        <pose frame="">0 0 0.046 0 0 0</pose>
        <geometry>
          <box>
            <size>0.80 0.5709 0.2</size>
          </box>
        </geometry>
      </collision>
      <collision name="base_link_collision_1">
        <pose frame="">0 0 0.185625 0 -0 0</pose>
        <geometry>
          <box>
            <size>0.78992 0.5709 0.12375</size>
          </box>
        </geometry>
      </collision>
      <collision name="base_link_fixed_joint_lump__camera/camera_link_collision_1">
        <pose frame="pan_gimbal_link">0 0 0.05 0 0.0 0</pose>
        <geometry>
          <box>
            <size>0.0078 0.13 0.0192</size>
          </box>
        </geometry>
        <surface>
          <contact>
            <ode>
              <kp>1e+13</kp>
              <kd>1</kd>
            </ode>
          </contact>
          <friction>
            <ode>
              <mu2>1</mu2>
              <fdir1>0 0 0</fdir1>
            </ode>
          </friction>
        </surface>
      </collision>
      <collision name="base_link_fixed_joint_lump__camera/camera_link_collision_2">
        <pose frame="">0.485 0 0.31 0 -0 0</pose>
        <geometry>
          <box>
            <size>0.0078 0.13 0.0192</size>
          </box>
        </geometry>
        <surface>
          <contact>
            <ode>
              <kp>1e+13</kp>
              <kd>1</kd>
            </ode>
          </contact>
          <friction>
            <ode>
              <mu2>1</mu2>
              <fdir1>0 0 0</fdir1>
            </ode>
          </friction>
        </surface>
      </collision>
      <collision name="base_link_fixed_joint_lump__camera/camera_link_collision_3">
        <pose frame="">0.473 0 0.260 0 0.5236 0</pose>
        <geometry>
          <box>
            <size>0.0078 0.13 0.0192</size>
          </box>
        </geometry>
        <surface>
          <contact>
            <ode>
              <kp>1e+13</kp>
              <kd>1</kd>
            </ode>
          </contact>
          <friction>
            <ode>
              <mu2>1</mu2>
              <fdir1>0 0 0</fdir1>
            </ode>
          </friction>
        </surface>
      </collision>
      <collision name="base_link_fixed_joint_lump__velodyne_base_link_collision_6">
        <pose frame="">0.403 0 0.36 0 -0 0</pose>
        <geometry>
          <cylinder>
            <length>0.0717</length>
            <radius>0.0516</radius>
          </cylinder>
        </geometry>
      </collision>
      <collision name="base_link_fixed_joint_lump__velodyne_gimbal_plate_base_link_collision_7">
        <pose frame="">0.403 0 0.410 0 -0 0</pose>
        <geometry>
          <box>
            <size>0.1 0.1 0.01</size>
          </box>
        </geometry>
      </collision>
      <collision name="base_link_fixed_joint_lump__sensor_tower_8">
        <pose frame="">0.374 0 0.215 0 -0 0</pose>
        <geometry>
          <box>
            <size>0.2 0.25 0.225</size>
          </box>
        </geometry>
      </collision>
      <collision name="base_link_fixed_joint_lump__computer_block_9">
        <pose frame="">0.050 0 0.155 0 -0 0</pose>
        <geometry>
          <box>
            <size>0.30 0.355 0.160</size>
          </box>
        </geometry>
      </collision>
      <visual name="Body_visual">
        <pose>0 0 -0.135 0 0 1.57</pose>
        <geometry>
          <mesh>
            <uri>meshes/hd2.dae</uri>
            <submesh>
              <name>Body</name>
              <center>false</center>
            </submesh>
          </mesh>
        </geometry>
        <material>
          <diffuse>1.0 1.0 1.0</diffuse>
          <specular>1.0 1.0 1.0</specular>
          <pbr>
            <metal>
              <albedo_map>materials/textures/HD2_Albedo.jpg</albedo_map>
              <metalness_map>materials/textures/HD2_Metalness.jpg</metalness_map>
              <roughness_map>materials/textures/HD2_Roughness.jpg</roughness_map>
            </metal>
          </pbr>
          <!-- fallback to script if no PBR support-->
          <script>
            <uri>materials/scripts/</uri>
            <uri>materials/textures/</uri>
            <name>HD/HD2_Diffuse</name>
          </script>
        </material>
      </visual>

      <!-- Based on Intel realsense D435 (intrinsics and distortion not modeled)-->
      <sensor name="camera_front" type="rgbd_camera">
        <camera name="camera_front">
          <horizontal_fov>1.5184</horizontal_fov>
          <lens>
            <intrinsics>
              <!-- fx = fy = width / ( 2 * tan (hfov / 2 ) ) -->
              <fx>168.61097</fx>
              <fy>168.61097</fy>
              <!-- cx = ( width + 1 ) / 2 -->
              <cx>160.5</cx>
              <!-- cy = ( height + 1 ) / 2 -->
              <cy>120.5</cy>
              <s>0</s>
            </intrinsics>
          </lens>
          <distortion>
            <k1>0.0</k1>
            <k2>0.0</k2>
            <k3>0.0</k3>
            <p1>0.0</p1>
            <p2>0.0</p2>
            <center>0.5 0.5</center>
          </distortion>
          <image>
            <width>320</width>
            <height>240</height>
            <format>R8G8B8</format>
          </image>
          <clip>
            <near>0.01</near>
            <far>300</far>
          </clip>
          <depth_camera>
            <clip>
              <near>0.1</near>
              <far>10</far>
            </clip>
          </depth_camera>
          <noise>
            <type>gaussian</type>
            <mean>0</mean>
            <stddev>0.007</stddev>
          </noise>
        </camera>
        <always_on>1</always_on>
        <update_rate>30</update_rate>
        <pose frame="">0.485 0 0.31 0 -0 0</pose>
      </sensor>
      <gravity>1</gravity>
      <velocity_decay/>
      <!-- Based on Intel realsense D435 (intrinsics and distortion not modeled)-->
      <sensor name="camera_down" type="rgbd_camera">
        <camera name="camera_down">
          <horizontal_fov>1.5184</horizontal_fov>
          <lens>
            <intrinsics>
              <!-- fx = fy = width / ( 2 * tan (hfov / 2 ) ) -->
              <fx>168.61097</fx>
              <fy>168.61097</fy>
              <!-- cx = ( width + 1 ) / 2 -->
              <cx>160.5</cx>
              <!-- cy = ( height + 1 ) / 2 -->
              <cy>120.5</cy>
              <s>0</s>
            </intrinsics>
          </lens>
          <distortion>
            <k1>0.0</k1>
            <k2>0.0</k2>
            <k3>0.0</k3>
            <p1>0.0</p1>
            <p2>0.0</p2>
            <center>0.5 0.5</center>
          </distortion>
          <image>
            <width>320</width>
            <height>240</height>
            <format>R8G8B8</format>
          </image>
          <clip>
            <near>0.01</near>
            <far>300</far>
          </clip>
          <depth_camera>
            <clip>
              <near>0.1</near>
              <far>10</far>
            </clip>
          </depth_camera>
          <noise>
            <type>gaussian</type>
            <mean>0</mean>
            <stddev>0.007</stddev>
          </noise>
        </camera>
        <always_on>1</always_on>
        <update_rate>30</update_rate>
        <pose frame="">0.473 0 0.260 0 0.5236 0</pose>
        <!-- 30 degree download look-->
      </sensor>
      <gravity>1</gravity>
      <velocity_decay/>
      <!-- Based on RPLidar S1 -->
      <sensor name="planar_laser" type="gpu_ray">
        <pose>0.403 0 0.127 0 -0 0</pose>
        <update_rate>10</update_rate>
        <lidar>
          <scan>
            <horizontal>
              <samples>920</samples>
              <resolution>1</resolution>
              <min_angle>-3.14159</min_angle>
              <max_angle>3.14159</max_angle>
            </horizontal>
          </scan>
          <range>
            <min>0.04</min>
            <max>25</max>
            <resolution>0.03</resolution>
          </range>
          <noise>
            <type>gaussian</type>
            <mean>0</mean>
            <stddev>0.01</stddev>
          </noise>
        </lidar>
      </sensor>
      <gravity>1</gravity>
      <velocity_decay/>
      <!-- OS1-64 3D Laser Configuration (10x2048 or 10x1024 or 20x1024 or 20x512 as possible (rate) x (hor. res.) configs)-->
      <sensor name="front_laser" type="gpu_lidar">
        <topic>marble/os1_cloud_node</topic>
        <ignition_frame_id>marble/os1_lidar</ignition_frame_id>
        <alwaysOn>1</alwaysOn>
        <visualize>true</visualize>
        <update_rate>20</update_rate>
        <lidar>
          <scan>
            <horizontal>
              <samples>1024</samples>
              <resolution>1</resolution>
              <min_angle>-3.14159</min_angle>
              <max_angle>3.14159</max_angle>
            </horizontal>
            <vertical>
              <samples>64</samples>
              <resolution>1</resolution>
              <min_angle>-0.2897</min_angle>
              <max_angle>0.2897</max_angle>
            </vertical>
          </scan>
          <range>
            <min>0.8</min>
            <max>20</max>
            <resolution>0.003</resolution>
          </range>
          <noise>
            <type>gaussian</type>
            <mean>0</mean>
            <stddev>0.03</stddev>
          </noise>
        </lidar>
        <pose frame="">0.403 0 0.36 0 -0 0</pose>
      </sensor>
      <!-- <sensor name='sensor' type='gpu_lidar'>
        <topic>marble/os1_cloud_node</topic>
        <ignition_frame_id>marble/os1_lidar</ignition_frame_id>
        <pose frame="">0.403 0 0.36 0 -0 0</pose>
        <update_rate>10</update_rate>
        <ray>
          <noise>
            <type>gaussian</type>
            <mean>0.0</mean>
            <stddev>0.02</stddev>
          </noise> 
          <scan>
              <horizontal>
              <samples>512</samples>
              <resolution>1</resolution>
              <min_angle>-3.14159</min_angle>
              <max_angle>3.14159</max_angle>
            </horizontal>
            <vertical>
              <samples>16</samples>
              <resolution>1</resolution>
              <min_angle>-0.2897247</min_angle>
              <max_angle>0.2897247</max_angle>
            </vertical>
          </scan>
          <range>
            <min>0.5</min>
            <max>25.0</max>
            <resolution>0.01</resolution>
          </range>
        </ray>
        <alwaysOn>1</alwaysOn>
        <visualize>true</visualize>
      </sensor> -->
      <sensor name="imu_sensor" type="imu">
        <always_on>1</always_on>
        <update_rate>50</update_rate>
        <imu>
          <enable_orientation>0</enable_orientation>
          <angular_velocity>
              <x>
                  <noise type="gaussian">
                      <mean>0</mean>
                      <stddev>0.009</stddev>
                      <bias_mean>0.00075</bias_mean>
                      <bias_stddev>0.005</bias_stddev>
                      <dynamic_bias_stddev>0.00002</dynamic_bias_stddev>
                      <dynamic_bias_correlation_time>400.0</dynamic_bias_correlation_time>
                      <precision>0.00025</precision>
                  </noise>
              </x>
              <y>
                  <noise type="gaussian">
                      <mean>0</mean>
                      <stddev>0.009</stddev>
                      <bias_mean>0.00075</bias_mean>
                      <bias_stddev>0.005</bias_stddev>
                      <dynamic_bias_stddev>0.00002</dynamic_bias_stddev>
                      <dynamic_bias_correlation_time>400.0</dynamic_bias_correlation_time>
                      <precision>0.00025</precision>
                  </noise>
              </y>
              <z>
                  <noise type="gaussian">
                      <mean>0</mean>
                      <stddev>0.009</stddev>
                      <bias_mean>0.00075</bias_mean>
                      <bias_stddev>0.005</bias_stddev>
                      <dynamic_bias_stddev>0.00002</dynamic_bias_stddev>
                      <dynamic_bias_correlation_time>400.0</dynamic_bias_correlation_time>
                      <precision>0.00025</precision>
                  </noise>
              </z>
          </angular_velocity>
          <linear_acceleration>
              <x>
                  <noise type="gaussian">
                      <mean>0</mean>
                      <stddev>0.021</stddev>
                      <bias_mean>0.05</bias_mean>
                      <bias_stddev>0.0075</bias_stddev>
                      <dynamic_bias_stddev>0.000375</dynamic_bias_stddev>
                      <dynamic_bias_correlation_time>175.0</dynamic_bias_correlation_time>
                      <precision>0.005</precision>
                  </noise>
              </x>
              <y>
                  <noise type="gaussian">
                      <mean>0</mean>
                      <stddev>0.021</stddev>
                      <bias_mean>0.05</bias_mean>
                      <bias_stddev>0.0075</bias_stddev>
                      <dynamic_bias_stddev>0.000375</dynamic_bias_stddev>
                      <dynamic_bias_correlation_time>175.0</dynamic_bias_correlation_time>
                      <precision>0.005</precision>
                  </noise>
              </y>
              <z>
                  <noise type="gaussian">
                      <mean>0</mean>
                      <stddev>0.021</stddev>
                      <bias_mean>0.05</bias_mean>
                      <bias_stddev>0.0075</bias_stddev>
                      <dynamic_bias_stddev>0.000375</dynamic_bias_stddev>
                      <dynamic_bias_correlation_time>175.0</dynamic_bias_correlation_time>
                      <precision>0.005</precision>
                  </noise>
              </z>
          </linear_acceleration>
         </imu>
       </sensor>
        </link>
        <!-- Left Track  -->
        <link name="left_track">
          <pose frame="">0 0.27 0.00 0 -0 0</pose>
          <inertial>
            <pose frame="">0 0 0 0 -0 0</pose>
            <mass>1.0</mass>
            <inertia> <!-- Inertia of a 6 kg box 0.1x0.258x0.72 m -->
              <ixx>0.00479</ixx>
              <ixy>0</ixy>
              <ixz>0</ixz>
              <iyy>0.02397</iyy>
              <iyz>0</iyz>
              <izz>0.02084 </izz>
            </inertia>
          </inertial>
          <collision name="left_track_box_collision">
            <geometry>
              <box>
                <size>0.49 0.1 0.218</size>
              </box>
            </geometry>
          </collision>
        </link>
        <link name="left_track_front_wheel">
          <pose frame="">0.360 0.26 0 -1.5707963267948966 -0 0</pose>
          <inertial>
            <pose frame="">0 0 0 0 -0 0</pose>
            <mass>6.0</mass>
            <inertia> <!-- Inertia of a 6 kg wheel 0.1x0.258x0.72 m -->
              <ixx>0.01332</ixx>
              <ixy>0</ixy>
              <ixz>0</ixz>
              <iyy>0.01332</iyy>
              <iyz>0</iyz>
              <izz>0.01664</izz>
            </inertia>
          </inertial>
          <collision name="front_left_wheel_link_collision">
            <geometry>
              <cylinder>
                <length>0.1</length>
                <radius>0.129</radius>
              </cylinder>
            </geometry>
          </collision>
        </link>
        <link name="left_track_rear_wheel">
          <pose frame="">-0.36 0.26 0 -1.5707963267948966 -0 0</pose>
          <inertial>
            <pose frame="">0 0 0 0 -0 0</pose>
            <mass>6.0</mass>
            <inertia> <!-- Inertia of a 6 kg wheel 0.1x0.258x0.72 m -->
              <ixx>0.02996</ixx>
              <ixy>0</ixy>
              <ixz>0</ixz>
              <iyy>0.04992</iyy>
              <iyz>0</iyz>
              <izz>0.04992</izz>
            </inertia>
          </inertial>
          <collision name="rear_left_wheel_link_collision">
            <geometry>
              <cylinder>
                <length>0.1</length>
                <radius>0.129</radius>
              </cylinder>
            </geometry>
          </collision>
        </link>
        <link name="left_track_center_wheel">
          <pose frame="">-0.0 0.26 0 -1.5707963267948966 -0 0</pose>
          <inertial>
            <pose frame="">0 0 0 0 -0 0</pose>
            <mass>6.0</mass>
            <inertia> <!-- Inertia of a 6 kg wheel 0.1x0.258x0.72 m -->
              <ixx>0.02996</ixx>
              <ixy>0</ixy>
              <ixz>0</ixz>
              <iyy>0.04992</iyy>
              <iyz>0</iyz>
              <izz>0.04992</izz>
            </inertia>
          </inertial>
          <collision name="center_left_wheel_link_collision">
            <geometry>
              <cylinder>
                <length>0.1</length>
                <radius>0.129</radius>
              </cylinder>
            </geometry>
          </collision>
        </link>
        <joint name="left_track_j" type="fixed">
          <child>left_track</child>
          <parent>base_link</parent>
        </joint>
        <joint name='left_front_track_wheel_j' type='revolute'>
            <child>left_track_front_wheel</child>
            <parent>base_link</parent>
            <axis>
                <xyz>0 0 1</xyz>
                <limit>
                  <lower>-1.79769e+308</lower>
                  <upper>1.79769e+308</upper>
                </limit>
            </axis>
        </joint>
        <joint name='left_rear_track_wheel_j' type='revolute'>
            <child>left_track_rear_wheel</child>
            <parent>base_link</parent>
            <axis>
                <xyz>0 0 1</xyz>
                <limit>
                  <lower>-1.79769e+308</lower>
                  <upper>1.79769e+308</upper>
                </limit>
            </axis>
        </joint>
        <joint name='left_center_track_wheel_j' type='revolute'>
            <child>left_track_center_wheel</child>
            <parent>base_link</parent>
            <axis>
                <xyz>0 0 1</xyz>
                <limit>
                  <lower>-1.79769e+308</lower>
                  <upper>1.79769e+308</upper>
                </limit>
            </axis>
        </joint>
        <!-- Right Track  -->
        <link name="right_track">
          <pose frame="">0 -0.27 0.00 0 -0 0</pose>
          <inertial>
            <pose frame="">0 0 0 0 -0 0</pose>
            <mass>1.0</mass>
            <inertia> <!-- Inertia of a 6 kg box 0.1x0.258x0.72 m -->
              <ixx>0.00479</ixx>
              <ixy>0</ixy>
              <ixz>0</ixz>
              <iyy>0.02397</iyy>
              <iyz>0</iyz>
              <izz>0.02084 </izz>
            </inertia>
          </inertial>
          <collision name="left_track_box_collision">
            <geometry>
              <box>
                <size>0.49 0.1 0.218</size>
              </box>
            </geometry>
          </collision>
        </link>
        <link name="right_track_front_wheel">
          <pose frame="">0.360 -0.26 0 -1.5707963267948966 -0 0</pose>
          <inertial>
            <pose frame="">0 0 0 0 -0 0</pose>
            <mass>6.0</mass>
            <inertia> <!-- Inertia of a 6 kg wheel 0.1x0.258x0.72 m -->
              <ixx>0.02996</ixx>
              <ixy>0</ixy>
              <ixz>0</ixz>
              <iyy>0.04992</iyy>
              <iyz>0</iyz>
              <izz>0.04992</izz>
            </inertia>
          </inertial>
          <collision name="front_right_wheel_link_collision">
            <geometry>
              <cylinder>
                <length>0.1</length>
                <radius>0.129</radius>
              </cylinder>
            </geometry>
          </collision>
        </link>
        <link name="right_track_rear_wheel">
          <pose frame="">-0.36 -0.26 0 -1.5707963267948966 -0 0</pose>
          <inertial>
            <pose frame="">0 0 0 0 -0 0</pose>
            <mass>6.0</mass>
            <inertia> <!-- Inertia of a 6 kg wheel 0.1x0.258x0.72 m -->
              <ixx>0.02996</ixx>
              <ixy>0</ixy>
              <ixz>0</ixz>
              <iyy>0.04992</iyy>
              <iyz>0</iyz>
              <izz>0.04992</izz>
            </inertia>
          </inertial>
          <collision name="rear_right_wheel_link_collision">
            <geometry>
              <cylinder>
                <length>0.1</length>
                <radius>0.129</radius>
              </cylinder>
            </geometry>
          </collision>
        </link>
        <link name="right_track_center_wheel">
          <pose frame="">-0.0 -0.26 0 -1.5707963267948966 -0 0</pose>
          <inertial>
            <pose frame="">0 0 0 0 -0 0</pose>
            <mass>6.0</mass>
            <inertia> <!-- Inertia of a 6 kg wheel 0.1x0.258x0.72 m -->
              <ixx>0.02996</ixx>
              <ixy>0</ixy>
              <ixz>0</ixz>
              <iyy>0.04992</iyy>
              <iyz>0</iyz>
              <izz>0.04992</izz>
            </inertia>
          </inertial>
          <collision name="center_left_wheel_link_collision">
            <geometry>
              <cylinder>
                <length>0.1</length>
                <radius>0.129</radius>
              </cylinder>
            </geometry>
          </collision>
        </link>
        <joint name="right_track_j" type="fixed">
          <child>right_track</child>
          <parent>base_link</parent>
        </joint>
        <joint name='right_front_track_wheel_j' type='revolute'>
            <child>right_track_front_wheel</child>
            <parent>base_link</parent>
            <axis>
                <xyz>0 0 1</xyz>
                <limit>
                    <lower>-1e+16</lower>
                    <upper>1e+16</upper>
                </limit>
            </axis>
        </joint>
        <joint name='right_rear_track_wheel_j' type='revolute'>
            <child>right_track_rear_wheel</child>
            <parent>base_link</parent>
            <axis>
                <xyz>0 0 1</xyz>
                <limit>
                    <lower>-1e+16</lower>
                    <upper>1e+16</upper>
                </limit>
            </axis>
        </joint>
        <joint name='right_center_track_wheel_j' type='revolute'>
            <child>right_track_center_wheel</child>
            <parent>base_link</parent>
            <axis>
                <xyz>0 0 1</xyz>
                <limit>
                    <lower>-1e+16</lower>
                    <upper>1e+16</upper>
                </limit>
            </axis>
        </joint>
        <plugin name='ignition::gazebo::systems::TrackController' filename='libignition-gazebo-track-controller-system.so'>
          <link>left_track</link>
          <min_velocity>-1</min_velocity>
          <max_velocity>1</max_velocity>
          <min_acceleration>-3</min_acceleration>
          <max_acceleration>3</max_acceleration>
        </plugin>
        <plugin name='ignition::gazebo::systems::TrackController' filename='libignition-gazebo-track-controller-system.so'>
          <link>right_track</link>
          <min_velocity>-1</min_velocity>
          <max_velocity>1</max_velocity>
          <min_acceleration>-3</min_acceleration>
          <max_acceleration>3</max_acceleration>
        </plugin>
        <!-- Gimbal Links + Joints -->
        <link name="pan_gimbal_link">
          <pose frame="">0.4056 -0.01122 0.4904 0 -0 0</pose>
          <inertial>
            <pose frame="">0 0 0 0 -0 0</pose>
            <mass>0.1</mass>
            <inertia>
              <ixx>0.000016875</ixx>
              <ixy>0</ixy>
              <ixz>0</ixz>
              <iyy>0.00000001</iyy>
              <iyz>0</iyz>
              <izz>0.000016875</izz>
            </inertia>
          </inertial>
          <collision name="pan_gimbal_link_collision">
            <pose frame="">0.0 0 0.0 0 -0 0</pose>
            <geometry>
              <cylinder>
                <length>0.045</length>
                <radius>0.014</radius>
              </cylinder>
            </geometry>
            <surface>
              <contact>
                <ode>
                  <kp>1e+07</kp>
                  <kd>1</kd>
                </ode>
              </contact>
            </surface>
          </collision>
          <visual name= "CameraPivot_visual">
            <pose>0 0 0 0 0 1.57</pose>
            <geometry>
              <mesh>
                <uri>meshes/hd2.dae</uri>
                <submesh>
                  <name>CameraPivot</name>
                  <center>true</center>
                </submesh>
              </mesh>
            </geometry>
            <material>
              <diffuse>1.0 1.0 1.0</diffuse>
              <specular>1.0 1.0 1.0</specular>
              <pbr>
                <metal>
                  <albedo_map>materials/textures/HD2_Albedo.jpg</albedo_map>
                  <metalness_map>materials/textures/HD2_Metalness.jpg</metalness_map>
                  <roughness_map>materials/textures/HD2_Roughness.jpg</roughness_map>
                </metal>
              </pbr>
              <script>
                <uri>materials/scripts/</uri>
                <uri>materials/textures/</uri>
                <name>HD2/HD2_Diffuse</name>
              </script>
            </material>
          </visual>
        </link>
        <link name="tilt_gimbal_link">
          <pose frame="">0.409 -0.008 0.5013 0 -0 0</pose>
          <inertial>
            <pose frame="">0 0 0 1.570796 -0 0</pose>
            <mass>0.1</mass>
            <inertia>
              <ixx>0.000016875</ixx>
              <ixy>0</ixy>
              <ixz>0</ixz>
              <iyy>0.00000001</iyy>
              <iyz>0</iyz>
              <izz>0.000016875</izz>
            </inertia>
          </inertial>
          <collision name="tilt_gimbal_link_collision">
            <pose frame="">0.0 0 0.0 1.570796 -0 0</pose>
            <geometry>
              <cylinder>
                <length>0.045</length>
                <radius>0.014</radius>
              </cylinder>
            </geometry>
            <surface>
              <contact>
                <ode>
                  <kp>1e+07</kp>
                  <kd>1</kd>
                </ode>
              </contact>
            </surface>
          </collision>

                    <visual name= "CameraTilt_visual">
                      <pose>0.005 0.015 0.038 0 0 -1.570796</pose>
                      <geometry>
                        <mesh>
                          <uri>meshes/hd2.dae</uri>
                          <submesh>
                            <name>CameraTilt</name>
                            <center>true</center>
                          </submesh>
                        </mesh>
                      </geometry>
                      <material>
                        <diffuse>1.0 1.0 1.0</diffuse>
                        <specular>1.0 1.0 1.0</specular>
                        <pbr>
                          <metal>
                            <albedo_map>materials/textures/HD2_Albedo.jpg</albedo_map>
                            <metalness_map>materials/textures/HD2_Metalness.jpg</metalness_map>
                            <roughness_map>materials/textures/HD2_Roughness.jpg</roughness_map>
                          </metal>
                        </pbr>
                        <!-- fallback to script if no PBR support-->
                        <script>
                          <uri>materials/scripts/</uri>
                          <uri>materials/textures/</uri>
                          <name>HD/HD2_Diffuse</name>
                        </script>
                      </material>
                    </visual>
                    <!-- Based on Intel realsense D435 (intrinsics and distortion not modeled)-->
                    <sensor name="camera_pan_tilt" type="rgbd_camera">
                      <camera name="camera_pan_tilt">
                        <horizontal_fov>1.5184</horizontal_fov>
                        <lens>
                          <intrinsics>
                            <!-- fx = fy = width / ( 2 * tan (hfov / 2 ) ) -->
                            <fx>337.22195</fx>
                            <fy>337.22195</fy>
                            <!-- cx = ( width + 1 ) / 2 -->
                            <cx>320.5</cx>
                            <!-- cy = ( height + 1 ) / 2 -->
                            <cy>240.5</cy>
                            <s>0</s>
                          </intrinsics>
                        </lens>
                        <distortion>
                          <k1>0.0</k1>
                          <k2>0.0</k2>
                          <k3>0.0</k3>
                          <p1>0.0</p1>
                          <p2>0.0</p2>
                          <center>0.5 0.5</center>
                        </distortion>
                        <image>
                          <width>640</width>
                          <height>480</height>
                          <format>R8G8B8</format>
                        </image>
                        <clip>
                          <near>0.01</near>
                          <far>300</far>
                        </clip>
                        <depth_camera>
                          <clip>
                            <near>0.1</near>
                            <far>10</far>
                          </clip>
                        </depth_camera>
                        <noise>
                          <type>gaussian</type>
                          <mean>0</mean>
                          <stddev>0.007</stddev>
                        </noise>
                      </camera>
                      <always_on>1</always_on>
                      <update_rate>30</update_rate>
                      <pose frame="">0.02 0 0.047725 0 0.0 0</pose>
                    </sensor>
                    <!-- <light name="flashlight_flashlight_light_source_lamp_light" type="spot">
                      <pose frame="">0.02 -0.01 0.076 3.141592653589793 1.5707963267948966 -0.0015926535897931</pose>
                      <attenuation>
                        <range>50</range>
                        <linear>1</linear>
                        <constant>0.1</constant>
                        <quadratic>0.0025</quadratic>
                      </attenuation>
                      <diffuse>0.8 0.8 0.5 1</diffuse>
                      <specular>0.8 0.8 0.5 1</specular>
                      <spot>
                        <inner_angle>2.8</inner_angle>
                        <outer_angle>2.9</outer_angle>
                        <falloff>1</falloff>
                      </spot>
                      <direction>0 0 -1</direction>
                    </light> -->
                  </link>
                  <joint name="pan_gimbal_joint" type="revolute">
                    <child>pan_gimbal_link</child>
                    <parent>base_link</parent>
                    <axis>
                      <xyz>0 0 1</xyz>
                      <limit>
                        <lower>-1e+16</lower>
                        <upper>1e+16</upper>
                        <effort>10</effort>
                      </limit>
                      <dynamics>
                        <spring_reference>0</spring_reference>
                        <spring_stiffness>0</spring_stiffness>
                        <damping>0.5</damping>
                        <friction>0.001</friction>
                      </dynamics>
                      <use_parent_model_frame>1</use_parent_model_frame>
                    </axis>
                  </joint>
                  <joint name="tilt_gimbal_joint" type="revolute">
                    <child>tilt_gimbal_link</child>
                    <parent>pan_gimbal_link</parent>
                    <axis>
                      <xyz>0 1 0</xyz>
                      <limit>
                        <lower>-1.5708</lower>
                        <!-- 90 degrees both direction (mechanical interference)-->
                        <upper>1.5708</upper>
                        <effort>10</effort>
                      </limit>
                      <dynamics>
                        <spring_reference>0</spring_reference>
                        <spring_stiffness>0</spring_stiffness>
                        <damping>0.5</damping>
                      </dynamics>
                      <use_parent_model_frame>1</use_parent_model_frame>
                    </axis>
                  </joint>
                  <!-- Gimbal Joints Plugins -->
                  <plugin filename="libignition-gazebo-joint-controller-system.so" name="ignition::gazebo::systems::JointController">
                    <joint_name>pan_gimbal_joint</joint_name>
                    <use_force_commands>true</use_force_commands>
                    <p_gain>0.4</p_gain>
                    <i_gain>10</i_gain>
                  </plugin>
                  <plugin filename="libignition-gazebo-joint-controller-system.so" name="ignition::gazebo::systems::JointController">
                    <joint_name>tilt_gimbal_joint</joint_name>
                    <use_force_commands>true</use_force_commands>
                    <p_gain>0.4</p_gain>
                    <i_gain>10</i_gain>
                  </plugin>
                  <plugin filename="libignition-gazebo-joint-state-publisher-system.so" name="ignition::gazebo::systems::JointStatePublisher">
                    <joint_name>pan_gimbal_joint</joint_name>
                    <joint_name>tilt_gimbal_joint</joint_name>
                  </plugin>
                  <static>0</static>
                  <plugin filename="ignition-gazebo-diff-drive-system" name="ignition::gazebo::systems::DiffDrive">
                    <left_joint>left_front_track_wheel_j</left_joint>
                    <left_joint>left_rear_track_wheel_j </left_joint>
                    <left_joint>left_center_track_wheel_j </left_joint>
                    <right_joint>right_front_track_wheel_j</right_joint>
                    <right_joint>right_rear_track_wheel_j</right_joint>
                    <right_joint>right_center_track_wheel_j</right_joint>
                    <wheel_separation>0.52</wheel_separation>
                    <wheel_radius>0.129</wheel_radius>
                    <odom_publish_frequency>100</odom_publish_frequency>
                    <topic>marble/cmd_vel</topic> #Custom topic that this system will subscribe to in order to receive command velocity messages. This element if optional, and the default value is /model/{name_of_model}/cmd_vel.
                    <odom_topic>marble/odometry</odom_topic>  Custom topic on which this system will publish odometry messages. This element if optional, and the default value is /model/{name_of_model}/odometry.
                    <tf_topic>marble/ tf_odom_to_baselink</tf_topic>
                    <frame_id>marble/odom</frame_id>
                    <child_frame_id>marble/base_link</child_frame_id>
                  </plugin>

                </model>
              </sdf>
